2020-12-06 10:01:26,561 - [test_login.py -->line:43] - INFO : ================================== 开始执行登录接口测试 ==================================
2020-12-06 10:01:26,562 - [http_request.py -->line:37] - INFO : 正在发送请求, 请求地址: http://42.192.88.224:8000/user/login/, 请求参数: {'username': 'aaaaaa', 'password': '111111'}, 参数类型: form-data, 请求头: None
2020-12-06 10:01:28,836 - [test_login.py -->line:86] - INFO : 预期结果: {'user_id': 3, 'username': 'aaaaaa'}, 实际结果: {'user_id': 3, 'username': 'aaaaaa'}， 断言结果: PASS
2020-12-06 10:01:28,883 - [http_request.py -->line:37] - INFO : 正在发送请求, 请求地址: http://42.192.88.224:8000/user/login/, 请求参数: {'username': 'zhzhzh', 'password': '123456'}, 参数类型: form-data, 请求头: None
2020-12-06 10:01:31,118 - [test_login.py -->line:86] - INFO : 预期结果: {'user_id': 83, 'username': 'zhzhzh'}, 实际结果: {'user_id': 83, 'username': 'zhzhzh'}， 断言结果: PASS
2020-12-06 10:01:31,164 - [http_request.py -->line:37] - INFO : 正在发送请求, 请求地址: http://42.192.88.224:8000/user/login/, 请求参数: {'username': 'zhzhzh1', 'password': '123456'}, 参数类型: form-data, 请求头: None
2020-12-06 10:01:33,393 - [test_login.py -->line:86] - INFO : 预期结果: {'user_id': 84, 'username': 'zhzhzh1'}, 实际结果: {'user_id': 84, 'username': 'zhzhzh1'}， 断言结果: PASS
2020-12-06 10:01:33,439 - [http_request.py -->line:37] - INFO : 正在发送请求, 请求地址: http://42.192.88.224:8000/user/login/, 请求参数: {'username': 'zhzhzh1', 'password': '123457'}, 参数类型: form-data, 请求头: None
2020-12-06 10:01:35,663 - [test_login.py -->line:86] - INFO : 预期结果: {'non_field_errors': ['无法使用提供的认证信息登录。']}, 实际结果: {'non_field_errors': ['无法使用提供的认证信息登录。']}， 断言结果: PASS
2020-12-06 10:01:35,713 - [http_request.py -->line:37] - INFO : 正在发送请求, 请求地址: http://42.192.88.224:8000/user/login/, 请求参数: {'username': '', 'password': '123458'}, 参数类型: form-data, 请求头: None
2020-12-06 10:01:37,753 - [test_login.py -->line:81] - ERROR :  :: {'non_field_errors': ['无法使用提供的认证信息登录。']} != {'username': ['该字段不能为空。']}
Traceback (most recent call last):
  File "D:\PyCharm Community Edition 2020.2.2\plugins\python-ce\helpers\pycharm\teamcity\diff_tools.py", line 32, in _patched_equals
    old(self, first, second, msg)
  File "C:\Py39\lib\unittest\case.py", line 831, in assertEqual
    assertion_func(first, second, msg=msg)
  File "C:\Py39\lib\unittest\case.py", line 1130, in assertDictEqual
    self.fail(self._formatMessage(msg, standardMsg))
  File "C:\Py39\lib\unittest\case.py", line 670, in fail
    raise self.failureException(msg)
AssertionError: {'non_field_errors': ['无法使用提供的认证信息登录。']} != {'username': ['该字段不能为空。']}
- {'non_field_errors': ['无法使用提供的认证信息登录。']}
+ {'username': ['该字段不能为空。']}

During handling of the above exception, another exception occurred:

Traceback (most recent call last):
  File "C:\Users\Administrator\PycharmProjects\api_automation-lianxi\test_cases\test_login.py", line 78, in test_login
    self.assertEqual(eval(case.expected_data), res)
  File "D:\PyCharm Community Edition 2020.2.2\plugins\python-ce\helpers\pycharm\teamcity\diff_tools.py", line 38, in _patched_equals
    raise error
teamcity.diff_tools.EqualsAssertionError:  :: {'non_field_errors': ['无法使用提供的认证信息登录。']} != {'username': ['该字段不能为空。']}
2020-12-06 10:01:37,801 - [http_request.py -->line:37] - INFO : 正在发送请求, 请求地址: http://42.192.88.224:8000/user/login/, 请求参数: {'username': 'zhzhzh1', 'password': ''}, 参数类型: form-data, 请求头: None
2020-12-06 10:01:39,840 - [test_login.py -->line:81] - ERROR :  :: {'non_field_errors': ['无法使用提供的认证信息登录。']} != {'password': ['该字段不能为空。']}
Traceback (most recent call last):
  File "D:\PyCharm Community Edition 2020.2.2\plugins\python-ce\helpers\pycharm\teamcity\diff_tools.py", line 32, in _patched_equals
    old(self, first, second, msg)
  File "C:\Py39\lib\unittest\case.py", line 831, in assertEqual
    assertion_func(first, second, msg=msg)
  File "C:\Py39\lib\unittest\case.py", line 1130, in assertDictEqual
    self.fail(self._formatMessage(msg, standardMsg))
  File "C:\Py39\lib\unittest\case.py", line 670, in fail
    raise self.failureException(msg)
AssertionError: {'non_field_errors': ['无法使用提供的认证信息登录。']} != {'password': ['该字段不能为空。']}
- {'non_field_errors': ['无法使用提供的认证信息登录。']}
+ {'password': ['该字段不能为空。']}

During handling of the above exception, another exception occurred:

Traceback (most recent call last):
  File "C:\Users\Administrator\PycharmProjects\api_automation-lianxi\test_cases\test_login.py", line 78, in test_login
    self.assertEqual(eval(case.expected_data), res)
  File "D:\PyCharm Community Edition 2020.2.2\plugins\python-ce\helpers\pycharm\teamcity\diff_tools.py", line 38, in _patched_equals
    raise error
teamcity.diff_tools.EqualsAssertionError:  :: {'non_field_errors': ['无法使用提供的认证信息登录。']} != {'password': ['该字段不能为空。']}
2020-12-06 10:01:39,888 - [http_request.py -->line:37] - INFO : 正在发送请求, 请求地址: http://42.192.88.224:8000/user/login/, 请求参数: {'username': 'zhz23h1', 'password': '12346'}, 参数类型: form-data, 请求头: None
2020-12-06 10:01:42,113 - [test_login.py -->line:86] - INFO : 预期结果: {'non_field_errors': ['无法使用提供的认证信息登录。']}, 实际结果: {'non_field_errors': ['无法使用提供的认证信息登录。']}， 断言结果: PASS
2020-12-06 10:01:42,159 - [test_login.py -->line:48] - INFO : ================================== 开始执行登录接口测试 ==================================
