2020-12-04 22:05:39,358 - [test_login.py -->line:39] - INFO : ================================== 开始执行登录接口测试 ==================================
2020-12-04 22:05:39,359 - [http_request.py -->line:37] - INFO : 正在发送请求, 请求地址: http://42.192.88.224:8000/user/login/, 请求参数: {'username': 'aaaaaa', 'password': '111111'}, 参数类型: form-data, 请求头: None
2020-12-04 22:05:41,628 - [test_login.py -->line:82] - INFO : 预期结果: {'user_id': 3, 'username': 'aaaaaa'}, 实际结果: {'user_id': 3, 'username': 'aaaaaa'}， 断言结果: PASS
2020-12-04 22:05:41,672 - [http_request.py -->line:37] - INFO : 正在发送请求, 请求地址: http://42.192.88.224:8000/user/login/, 请求参数: {'username': 'aaaaaa', 'password': '111111'}, 参数类型: form-data, 请求头: None
2020-12-04 22:05:43,900 - [test_login.py -->line:77] - ERROR : {'user_id': 3, 'username': 'aaaaaa1'} != {'user_id': 3, 'username': 'aaaaaa'}
- {'user_id': 3, 'username': 'aaaaaa1'}
?                                   -

+ {'user_id': 3, 'username': 'aaaaaa'}
Traceback (most recent call last):
  File "C:\Users\Administrator\PycharmProjects\api_automation-lianxi\test_cases\test_login.py", line 74, in test_login
    self.assertEqual(eval(case.expected_data), res)
  File "C:\Py39\lib\unittest\case.py", line 831, in assertEqual
    assertion_func(first, second, msg=msg)
  File "C:\Py39\lib\unittest\case.py", line 1130, in assertDictEqual
    self.fail(self._formatMessage(msg, standardMsg))
  File "C:\Py39\lib\unittest\case.py", line 670, in fail
    raise self.failureException(msg)
AssertionError: {'user_id': 3, 'username': 'aaaaaa1'} != {'user_id': 3, 'username': 'aaaaaa'}
- {'user_id': 3, 'username': 'aaaaaa1'}
?                                   -

+ {'user_id': 3, 'username': 'aaaaaa'}
2020-12-04 22:05:43,940 - [test_login.py -->line:44] - INFO : ================================== 开始执行登录接口测试 ==================================
